package exception;

/*
class A {
	private int[] arr = new int[3];
	
	A() {
		arr[0] = 0;
		arr[1] = 10;
		arr[2] = 20;
	}
	
	public void z(int first, int second) {
		try {
			System.out.println(arr[first] / arr[second]);
		}   
			catch (Exception e) {
			//System.out.println(e.getMessage());
			e.printStackTrace(); 
			
			
			
			catch (ArrayIndexOutOfBoundsException e) {
				System.out.println("ArrayIndexOutOfVoundsException");
		}	catch (ArithmeticException e) {
				System.out.println("ArithmeticException");
		}	catch (Exception e) {
				System.out.println("Exception");
		}
			
			
			catch (Exception e) {       //Exception이 다른 예외보다 먼저 나왔다는 경고
				System.out.println("Exception");
		}   catch (ArrayIndexOutOfBoundsException e) {
				System.out.println("ArrayIndexOutOfBoundsException");
		}   catch (ArithmeticException e) {
				System.out.println("ArithmeticException");
		}
		
	}
}

public class ExceptionEx1 {

	public static void main(String[] args) {
		A a = new A();
		//a.z(10, 1);
		//a.z(1, 0);
		//a.z(10, 1);
		a.z(10, 0);
		a.z(1, 0);
		a.z(2, 1);
	}

}
*/
